[2024-05-12T15:22:32.861+0000] {local_task_job_runner.py:120} INFO - ::group::Pre task execution logs
[2024-05-12T15:22:32.880+0000] {taskinstance.py:2076} INFO - Dependencies all met for dep_context=non-requeueable deps ti=<TaskInstance: web_article_scraping.dvc_add_and_push manual__2024-05-12T15:22:17.679106+00:00 [queued]>
[2024-05-12T15:22:32.887+0000] {taskinstance.py:2076} INFO - Dependencies all met for dep_context=requeueable deps ti=<TaskInstance: web_article_scraping.dvc_add_and_push manual__2024-05-12T15:22:17.679106+00:00 [queued]>
[2024-05-12T15:22:32.888+0000] {taskinstance.py:2306} INFO - Starting attempt 1 of 1
[2024-05-12T15:22:32.898+0000] {taskinstance.py:2330} INFO - Executing <Task(BashOperator): dvc_add_and_push> on 2024-05-12 15:22:17.679106+00:00
[2024-05-12T15:22:32.904+0000] {warnings.py:110} WARNING - /home/***/.local/lib/python3.12/site-packages/***/task/task_runner/standard_task_runner.py:61: DeprecationWarning: This process (pid=4138) is multi-threaded, use of fork() may lead to deadlocks in the child.
  pid = os.fork()

[2024-05-12T15:22:32.905+0000] {standard_task_runner.py:63} INFO - Started process 4140 to run task
[2024-05-12T15:22:32.905+0000] {standard_task_runner.py:90} INFO - Running: ['***', 'tasks', 'run', 'web_article_scraping', 'dvc_add_and_push', 'manual__2024-05-12T15:22:17.679106+00:00', '--job-id', '68', '--raw', '--subdir', 'DAGS_FOLDER/mlops_dag.py', '--cfg-path', '/tmp/tmp1xi8o6nz']
[2024-05-12T15:22:32.906+0000] {standard_task_runner.py:91} INFO - Job 68: Subtask dvc_add_and_push
[2024-05-12T15:22:32.942+0000] {task_command.py:426} INFO - Running <TaskInstance: web_article_scraping.dvc_add_and_push manual__2024-05-12T15:22:17.679106+00:00 [running]> on host 8b349270b58a
[2024-05-12T15:22:33.005+0000] {taskinstance.py:2648} INFO - Exporting env vars: AIRFLOW_CTX_DAG_OWNER='***' AIRFLOW_CTX_DAG_ID='web_article_scraping' AIRFLOW_CTX_TASK_ID='dvc_add_and_push' AIRFLOW_CTX_EXECUTION_DATE='2024-05-12T15:22:17.679106+00:00' AIRFLOW_CTX_TRY_NUMBER='1' AIRFLOW_CTX_DAG_RUN_ID='manual__2024-05-12T15:22:17.679106+00:00'
[2024-05-12T15:22:33.006+0000] {taskinstance.py:430} INFO - ::endgroup::
[2024-05-12T15:22:33.007+0000] {subprocess.py:63} INFO - Tmp dir root location: /tmp
[2024-05-12T15:22:33.008+0000] {subprocess.py:75} INFO - Running command: ['/usr/bin/bash', '-c', '\ncd /opt/***/dags && \\\n"C:\\Users\\shaklu\\AppData\\Local\\Packages\\PythonSoftwareFoundation.Python.3.12_qbz5n2kfra8p0\\LocalCache\\local-packages\\Python312\\Scripts\\dvc.exe" remote add -d mygoogleDrive gdrive://1akLltC_11ZTBzZF-D4cZt_sZIf-jheJE && \\\n"C:\\Users\\shaklu\\AppData\\Local\\Packages\\PythonSoftwareFoundation.Python.3.12_qbz5n2kfra8p0\\LocalCache\\local-packages\\Python312\\Scripts\\dvc.exe" add extracted_data.csv && \\\ngit add . && \\\ngit commit -m "committed via ***" && \\\n"C:\\Users\\shaklu\\AppData\\Local\\Packages\\PythonSoftwareFoundation.Python.3.12_qbz5n2kfra8p0\\LocalCache\\local-packages\\Python312\\Scripts\\dvc.exe" push -r mygoogleDrive && \\\ngit push']
[2024-05-12T15:22:33.018+0000] {subprocess.py:86} INFO - Output:
[2024-05-12T15:22:33.020+0000] {subprocess.py:93} INFO - /usr/bin/bash: line 3: C:\Users\shaklu\AppData\Local\Packages\PythonSoftwareFoundation.Python.3.12_qbz5n2kfra8p0\LocalCache\local-packages\Python312\Scripts\dvc.exe: command not found
[2024-05-12T15:22:33.020+0000] {subprocess.py:97} INFO - Command exited with return code 127
[2024-05-12T15:22:33.021+0000] {taskinstance.py:441} INFO - ::group::Post task execution logs
[2024-05-12T15:22:33.029+0000] {taskinstance.py:2905} ERROR - Task failed with exception
Traceback (most recent call last):
  File "/home/airflow/.local/lib/python3.12/site-packages/airflow/models/taskinstance.py", line 465, in _execute_task
    result = _execute_callable(context=context, **execute_callable_kwargs)
             ^^^^^^^^^^^^^^^^^^^^^^^^^^^^^^^^^^^^^^^^^^^^^^^^^^^^^^^^^^^^^
  File "/home/airflow/.local/lib/python3.12/site-packages/airflow/models/taskinstance.py", line 432, in _execute_callable
    return execute_callable(context=context, **execute_callable_kwargs)
           ^^^^^^^^^^^^^^^^^^^^^^^^^^^^^^^^^^^^^^^^^^^^^^^^^^^^^^^^^^^^
  File "/home/airflow/.local/lib/python3.12/site-packages/airflow/models/baseoperator.py", line 400, in wrapper
    return func(self, *args, **kwargs)
           ^^^^^^^^^^^^^^^^^^^^^^^^^^^
  File "/home/airflow/.local/lib/python3.12/site-packages/airflow/operators/bash.py", line 243, in execute
    raise AirflowException(
airflow.exceptions.AirflowException: Bash command failed. The command returned a non-zero exit code 127.
[2024-05-12T15:22:33.033+0000] {taskinstance.py:1206} INFO - Marking task as FAILED. dag_id=web_article_scraping, task_id=dvc_add_and_push, run_id=manual__2024-05-12T15:22:17.679106+00:00, execution_date=20240512T152217, start_date=20240512T152232, end_date=20240512T152233
[2024-05-12T15:22:33.042+0000] {standard_task_runner.py:110} ERROR - Failed to execute job 68 for task dvc_add_and_push (Bash command failed. The command returned a non-zero exit code 127.; 4140)
[2024-05-12T15:22:33.078+0000] {local_task_job_runner.py:240} INFO - Task exited with return code 1
[2024-05-12T15:22:33.091+0000] {taskinstance.py:3498} INFO - 0 downstream tasks scheduled from follow-on schedule check
[2024-05-12T15:22:33.092+0000] {local_task_job_runner.py:222} INFO - ::endgroup::
